Traceback (most recent call last):
  File "./device1_acc.py", line 23, in <module>
    conn = Client(address,authkey=b"password")
  File "/usr/lib/python3.8/multiprocessing/connection.py", line 508, in Client
    answer_challenge(c, authkey)
  File "/usr/lib/python3.8/multiprocessing/connection.py", line 752, in answer_challenge
    message = connection.recv_bytes(256)         # reject large message
  File "/usr/lib/python3.8/multiprocessing/connection.py", line 216, in recv_bytes
    buf = self._recv_bytes(maxlength)
  File "/usr/lib/python3.8/multiprocessing/connection.py", line 414, in _recv_bytes
    buf = self._recv(4)
  File "/usr/lib/python3.8/multiprocessing/connection.py", line 379, in _recv
    chunk = read(handle, remaining)
KeyboardInterrupt
Traceback (most recent call last):
  File "./device1_acc.py", line 23, in <module>
    conn = Client(address,authkey=b"password")
  File "/usr/lib/python3.8/multiprocessing/connection.py", line 508, in Client
    answer_challenge(c, authkey)
  File "/usr/lib/python3.8/multiprocessing/connection.py", line 752, in answer_challenge
    message = connection.recv_bytes(256)         # reject large message
  File "/usr/lib/python3.8/multiprocessing/connection.py", line 216, in recv_bytes
    buf = self._recv_bytes(maxlength)
  File "/usr/lib/python3.8/multiprocessing/connection.py", line 414, in _recv_bytes
    buf = self._recv(4)
  File "/usr/lib/python3.8/multiprocessing/connection.py", line 379, in _recv
    chunk = read(handle, remaining)
ConnectionResetError: [Errno 104] 连接被对方重设
0,1,2,3
Traceback (most recent call last):
  File "./device1_acc.py", line 59, in <module>
    myNN = myNN.cuda()
  File "/home/fiee/.local/lib/python3.8/site-packages/torch/nn/modules/module.py", line 491, in cuda
    return self._apply(lambda t: t.cuda(device))
  File "/home/fiee/.local/lib/python3.8/site-packages/torch/nn/modules/module.py", line 387, in _apply
    module._apply(fn)
  File "/home/fiee/.local/lib/python3.8/site-packages/torch/nn/modules/module.py", line 409, in _apply
    param_applied = fn(param)
  File "/home/fiee/.local/lib/python3.8/site-packages/torch/nn/modules/module.py", line 491, in <lambda>
    return self._apply(lambda t: t.cuda(device))
RuntimeError: CUDA error: out of memory
0,1,2,3
0,1,2,3
Traceback (most recent call last):
  File "./device1_acc.py", line 59, in <module>
    myNN = myNN.cuda()
  File "/home/fiee/.local/lib/python3.8/site-packages/torch/nn/modules/module.py", line 491, in cuda
    return self._apply(lambda t: t.cuda(device))
  File "/home/fiee/.local/lib/python3.8/site-packages/torch/nn/modules/module.py", line 387, in _apply
    module._apply(fn)
  File "/home/fiee/.local/lib/python3.8/site-packages/torch/nn/modules/module.py", line 409, in _apply
    param_applied = fn(param)
  File "/home/fiee/.local/lib/python3.8/site-packages/torch/nn/modules/module.py", line 491, in <lambda>
    return self._apply(lambda t: t.cuda(device))
RuntimeError: CUDA error: out of memory
